Workbook

Sheet power_conf
A1: season | B1: team_id | C1: team_name | D1: Conference | E1: power_conf | F1: power_conf_extra
A2: 2008 | B2: 44 | C2: American | D2: {=_xlfn.XLOOKUP(1, ('team lookup'!$C$3:$C$97 = B2) * ('team lookup'!$A$3:$A$97 <= A2) * (IF('team lookup'!$B$3:$B$97 = "", 9999, 'team lookup'!$B$3:$B$97) >= A2), 'team lookup'!$E$3:$E$97, "Other" )} -> Other | E2: =IF(OR(D2="ACC", D2="SEC", D2="Big12"), 1,0) -> 0 | F2: =IF(D2<>"Other", 1,0) -> 0
A3: 2008 | B3: 12 | C3: Arizona | D3: {=_xlfn.XLOOKUP(1, ('team lookup'!$C$3:$C$97 = B3) * ('team lookup'!$A$3:$A$97 <= A3) * (IF('team lookup'!$B$3:$B$97 = "", 9999, 'team lookup'!$B$3:$B$97) >= A3), 'team lookup'!$E$3:$E$97, "Other" )} -> Other | E3: =IF(OR(D3="ACC", D3="SEC", D3="Big12"), 1,0) -> 0 | F3: =IF(D3<>"Other", 1,0) -> 0
A4: 2008 | B4: 8 | C4: Arkansas | D4: {=_xlfn.XLOOKUP(1, ('team lookup'!$C$3:$C$97 = B4) * ('team lookup'!$A$3:$A$97 <= A4) * (IF('team lookup'!$B$3:$B$97 = "", 9999, 'team lookup'!$B$3:$B$97) >= A4), 'team lookup'!$E$3:$E$97, "Other" )} -> SEC | E4: =IF(OR(D4="ACC", D4="SEC", D4="Big12"), 1,0) -> 1 | F4: =IF(D4<>"Other", 1,0) -> 1
A5: 2008 | B5: 2046 | C5: Austin Peay | D5: {=_xlfn.XLOOKUP(1, ('team lookup'!$C$3:$C$97 = B5) * ('team lookup'!$A$3:$A$97 <= A5) * (IF('team lookup'!$B$3:$B$97 = "", 9999, 'team lookup'!$B$3:$B$97) >= A5), 'team lookup'!$E$3:$E$97, "Other" )} -> Other | E5: =IF(OR(D5="ACC", D5="SEC", D5="Big12"), 1,0) -> 0 | F5: =IF(D5<>"Other", 1,0) -> 0
A6: 2008 | B6: 239 | C6: Baylor | D6: {=_xlfn.XLOOKUP(1, ('team lookup'!$C$3:$C$97 = B6) * ('team lookup'!$A$3:$A$97 <= A6) * (IF('team lookup'!$B$3:$B$97 = "", 9999, 'team lookup'!$B$3:$B$97) >= A6), 'team lookup'!$E$3:$E$97, "Other" )} -> Big12 | E6: =IF(OR(D6="ACC", D6="SEC", D6="Big12"), 1,0) -> 1 | F6: =IF(D6<>"Other", 1,0) -> 1
A7: 2008 | B7: 2057 | C7: Belmont | D7: {=_xlfn.XLOOKUP(1, ('team lookup'!$C$3:$C$97 = B7) * ('team lookup'!$A$3:$A$97 <= A7) * (IF('team lookup'!$B$3:$B$97 = "", 9999, 'team lookup'!$B$3:$B$97) >= A7), 'team lookup'!$E$3:$E$97, "Other" )} -> Other | E7: =IF(OR(D7="ACC", D7="SEC", D7="Big12"), 1,0) -> 0 | F7: =IF(D7<>"Other", 1,0) -> 0
A8: 2008 | B8: 68 | C8: Boise St | D8: {=_xlfn.XLOOKUP(1, ('team lookup'!$C$3:$C$97 = B8) * ('team lookup'!$A$3:$A$97 <= A8) * (IF('team lookup'!$B$3:$B$97 = "", 9999, 'team lookup'!$B$3:$B$97) >= A8), 'team lookup'!$E$3:$E$97, "Other" )} -> Other | E8: =IF(OR(D8="ACC", D8="SEC", D8="Big12"), 1,0) -> 0 | F8: =IF(D8<>"Other", 1,0) -> 0
A9: 2008 | B9: 2086 | C9: Butler | D9: {=_xlfn.XLOOKUP(1, ('team lookup'!$C$3:$C$97 = B9) * ('team lookup'!$A$3:$A$97 <= A9) * (IF('team lookup'!$B$3:$B$97 = "", 9999, 'team lookup'!$B$3:$B$97) >= A9), 'team lookup'!$E$3:$E$97, "Other" )} -> Other | E9: =IF(OR(D9="ACC", D9="SEC", D9="Big12"), 1,0) -> 0 | F9: =IF(D9<>"Other", 1,0) -> 0
A10: 2008 | B10: 252 | C10: BYU | D10: {=_xlfn.XLOOKUP(1, ('team lookup'!$C$3:$C$97 = B10) * ('team lookup'!$A$3:$A$97 <= A10) * (IF('team lookup'!$B$3:$B$97 = "", 9999, 'team lookup'!$B$3:$B$97) >= A10), 'team lookup'!$E$3:$E$97, "Other" )} -> Other | E10: =IF(OR(D10="ACC", D10="SEC", D10="Big12"), 1,0) -> 0 | F10: =IF(D10<>"Other", 1,0) -> 0
A11: 2008 | B11: 228 | C11: Clemson | D11: {=_xlfn.XLOOKUP(1, ('team lookup'!$C$3:$C$97 = B11) * ('team lookup'!$A$3:$A$97 <= A11) * (IF('team lookup'!$B$3:$B$97 = "", 9999, 'team lookup'!$B$3:$B$97) >= A11), 'team lookup'!$E$3:$E$97, "Other" )} -> ACC | E11: =IF(OR(D11="ACC", D11="SEC", D11="Big12"), 1,0) -> 1 | F11: =IF(D11<>"Other", 1,0) -> 1
A12: 2008 | B12: 172 | C12: Cornell | D12: {=_xlfn.XLOOKUP(1, ('team lookup'!$C$3:$C$97 = B12) * ('team lookup'!$A$3:$A$97 <= A12) * (IF('team lookup'!$B$3:$B$97 = "", 9999, 'team lookup'!$B$3:$B$97) >= A12), 'team lookup'!$E$3:$E$97, "Other" )} -> Other | E12: =IF(OR(D12="ACC", D12="SEC", D12="Big12"), 1,0) -> 0 | F12: =IF(D12<>"Other", 1,0) -> 0
A13: 2008 | B13: 2166 | C13: Davidson | D13: {=_xlfn.XLOOKUP(1, ('team lookup'!$C$3:$C$97 = B13) * ('team lookup'!$A$3:$A$97 <= A13) * (IF('team lookup'!$B$3:$B$97 = "", 9999, 'team lookup'!$B$3:$B$97) >= A13), 'team lookup'!$E$3:$E$97, "Other" )} -> Other | E13: =IF(OR(D13="ACC", D13="SEC", D13="Big12"), 1,0) -> 0 | F13: =IF(D13<>"Other", 1,0) -> 0
... A1212: 2026 | B1212: 2750 | C1212: Wright St | D1212: {=_xlfn.XLOOKUP(1, ('team lookup'!$C$3:$C$97 = B1212) * ('team lookup'!$A$3:$A$97 <= A1212) * (IF('team lookup'!$B$3:$B$97 = "", 9999, 'team lookup'!$B$3:$B$97) >= A1212), 'team lookup'!$E$3:$E$97, "Other" )} -> Other | E1212: =IF(OR(D1212="ACC", D1212="SEC", D1212="Big12"), 1,0) -> 0 | F1212: =IF(D1212<>"Other", 1,0) -> 0

Sheet team lookup
A1: Traditional Power Conferences: ACC, SEC, Big12…. Power Conf Extra includes Big10 and BigEast too
A2: season_start | B2: season_end | C2: team_id | D2: team_name | E2: conference
A3: 2008 | C3: 52 | D3: Florida St | E3: ACC
A4: 2008 | C4: 103 | D4: Boston College | E4: ACC
A5: 2008 | B5: 2014 | C5: 120 | D5: Maryland | E5: ACC
A6: 2008 | C6: 154 | D6: Wake Forest | E6: ACC
A7: 2008 | C7: 228 | D7: Clemson | E7: ACC
A8: 2008 | C8: 152 | D8: NC State | E8: ACC
A9: 2008 | C9: 259 | D9: Virginia Tech | E9: ACC
A10: 2008 | C10: 59 | D10: Georgia Tech | E10: ACC
A11: 2008 | C11: 153 | D11: North Carolina | E11: ACC
A12: 2008 | C12: 2390 | D12: Miami | E12: ACC
A13: 2008 | C13: 258 | D13: Virginia | E13: ACC
A14: 2008 | C14: 150 | D14: Duke | E14: ACC
A15: 2014 | C15: 221 | D15: Pitt | E15: ACC
A16: 2014 | C16: 183 | D16: Syracuse | E16: ACC
A17: 2014 | C17: 87 | D17: Notre Dame | E17: ACC
... A37: 2025 | C37: 251 | D37: Texas | E37: SEC
A38: 2008 | B38: 2024 | C38: 251 | D38: Texas | E38: Big12
A39: 2008 | C39: 2305 | D39: Kansas | E39: Big12
A40: 2008 | C40: 2306 | D40: Kansas St | E40: Big12
A41: 2008 | B41: 2024 | C41: 201 | D41: Oklahoma | E41: Big12
A42: 2008 | C42: 239 | D42: Baylor | E42: Big12
A43: 2008 | B43: 2012 | C43: 245 | D43: Texas A&M | E43: Big12
A44: 2008 | B44: 2011 | C44: 158 | D44: Nebraska | E44: Big12
A45: 2008 | C45: 2641 | D45: Texas Tech | E45: Big12
A46: 2008 | C46: 197 | D46: Oklahoma St | E46: Big12
A47: 2008 | B47: 2012 | C47: 142 | D47: Missouri | E47: Big12
A48: 2008 | C48: 66 | D48: Iowa State | E48: Big12
A49: 2008 | B49: 2011 | C49: 38 | D49: Colorado | E49: Big12
A50: 2013 | C50: 2628 | D50: TCU | E50: Big12
A51: 2013 | C51: 277 | D51: West Virginia | E51: Big12
A52: 2024 | C52: 248 | D52: Houston | E52: Big12
A53: 2024 | C53: 252 | D53: BYU | E53: Big12
A54: 2024 | C54: 2132 | D54: Cincinnati | E54: Big12
A55: 2024 | C55: 2116 | D55: UCF | E55: Big12
A56: 2025 | C56: 12 | D56: Arizona | E56: Big12
A57: 2025 | C57: 9 | D57: Arizona St | E57: Big12
A58: 2025 | C58: 254 | D58: Utah | E58: Big12
A59: 2025 | C59: 38 | D59: Colorado | E59: Big12
...
